<?xml version="1.0" encoding="utf-8"?>
<!-- This URDF was automatically created by SolidWorks to URDF Exporter! Originally created by Stephen Brawner (brawner@gmail.com) 
     Commit Version: 1.6.0-4-g7f85cfe  Build Version: 1.6.7995.38578
     For more information, please see http://wiki.ros.org/sw_urdf_exporter -->
<robot
  name="diablo_mesh">
  <link
    name="base_link">
    <inertial>
      <origin
        xyz="0.020214 1.4086E-08 0.0092665"
        rpy="0 0 0" />
      <mass
        value="11.639" />
      <inertia
        ixx="0.071628"
        ixy="-5.9879E-09"
        ixz="-0.00097471"
        iyy="0.16274"
        iyz="-1.6369E-08"
        izz="0.14673" />
    </inertial>
    <visual>
      <origin
        xyz="0 0 0"
        rpy="0 0 0" />
      <geometry>
        <mesh
          filename="../meshes/base_link.STL" />
      </geometry>
      <material
        name="">
        <color
          rgba="0.79216 0.81961 0.93333 1" />
      </material>
    </visual>
    <collision>
      <origin
        xyz="0 0 0"
        rpy="0 0 0" />
      <geometry>
        <mesh
          filename="../meshes/base_link.STL" />
      </geometry>
    </collision>
  </link>
  <link
    name="left_motor">
    <inertial>
      <origin
        xyz="0.0012043 -9.954E-08 -0.066749"
        rpy="0 0 0" />
      <mass
        value="1.3837" />
      <inertia
        ixx="0.003352"
        ixy="2.7785E-09"
        ixz="-6.5913E-05"
        iyy="0.0034908"
        iyz="4.5045E-10"
        izz="0.0034856" />
    </inertial>
    <visual>
      <origin
        xyz="0 0 0"
        rpy="0 0 0" />
      <geometry>
        <mesh
          filename="../meshes/left_motor.STL" />
      </geometry>
      <material
        name="">
        <color
          rgba="0.62745 0.62745 0.62745 1" />
      </material>
    </visual>
    <collision>
      <origin
        xyz="0 0 0"
        rpy="0 0 0" />
      <geometry>
        <mesh
          filename="../meshes/left_motor.STL" />
      </geometry>
    </collision>
  </link>
  <joint
    name="left_j4"
    type="continuous">
    <origin
      xyz="0 0.18755 0"
      rpy="1.5708 0.13433 -3.1416" />
    <parent
      link="base_link" />
    <child
      link="left_motor" />
    <axis
      xyz="0 0 -1" />
  </joint>
  <link
    name="left_leg1">
    <inertial>
      <origin
        xyz="0.056675 -0.014633 -0.0079998"
        rpy="0 0 0" />
      <mass
        value="0.10382" />
      <inertia
        ixx="3.6972E-05"
        ixy="2.4106E-05"
        ixz="4.3699E-10"
        iyy="0.00029278"
        iyz="-4.1243E-11"
        izz="0.00032532" />
    </inertial>
    <visual>
      <origin
        xyz="0 0 0"
        rpy="0 0 0" />
      <geometry>
        <mesh
          filename="../meshes/left_leg1.STL" />
      </geometry>
      <material
        name="">
        <color
          rgba="0.62745 0.62745 0.62745 1" />
      </material>
    </visual>
    <collision>
      <origin
        xyz="0 0 0"
        rpy="0 0 0" />
      <geometry>
        <mesh
          filename="../meshes/left_leg1.STL" />
      </geometry>
    </collision>
  </link>
  <joint
    name="left_j1"
    type="continuous">
    <origin
      xyz="0 0 0"
      rpy="0 0 -2.8729" />
    <parent
      link="left_motor" />
    <child
      link="left_leg1" />
    <axis
      xyz="0 0 -1" />
  </joint>
  <link
    name="left_leg2">
    <inertial>
      <origin
        xyz="0.092381 7.2105E-07 0.012349"
        rpy="0 0 0" />
      <mass
        value="0.18218" />
      <inertia
        ixx="4.1372E-05"
        ixy="5.1445E-09"
        ixz="-7.3659E-06"
        iyy="0.00048219"
        iyz="2.5521E-11"
        izz="0.00050441" />
    </inertial>
    <visual>
      <origin
        xyz="0 0 0"
        rpy="0 0 0" />
      <geometry>
        <mesh
          filename="../meshes/left_leg2.STL" />
      </geometry>
      <material
        name="">
        <color
          rgba="0.62745 0.62745 0.62745 1" />
      </material>
    </visual>
    <collision>
      <origin
        xyz="0 0 0"
        rpy="0 0 0" />
      <geometry>
        <mesh
          filename="../meshes/left_leg2.STL" />
      </geometry>
    </collision>
  </link>
  <joint
    name="left_j2"
    type="continuous">
    <origin
      xyz="0.14 0 0"
      rpy="0 0 2.8729" />
    <parent
      link="left_leg1" />
    <child
      link="left_leg2" />
    <axis
      xyz="0 0 1" />
  </joint>
  <link
    name="left_wheel">
    <inertial>
      <origin
        xyz="1.7359E-08 -1.5164E-10 5.0791E-09"
        rpy="0 0 0" />
      <mass
        value="2.9494" />
      <inertia
        ixx="0.0069338"
        ixy="2.8693E-09"
        ixz="4.6779E-09"
        iyy="0.006934"
        iyz="-5.0441E-11"
        izz="0.012567" />
    </inertial>
    <visual>
      <origin
        xyz="0 0 0"
        rpy="0 0 0" />
      <geometry>
        <mesh
          filename="../meshes/left_wheel.STL" />
      </geometry>
      <material
        name="">
        <color
          rgba="0.69804 0.69804 0.69804 1" />
        <texture
          filename="../textures/0a6c950e073a74d2e5cfa0c785a44257.jpg" />
      </material>
    </visual>
    <collision>
      <origin
        xyz="0 0 0"
        rpy="0 0 0" />
      <geometry>
        <mesh
          filename="../meshes/left_wheel.STL" />
      </geometry>
    </collision>
  </link>
  <joint
    name="left_j3"
    type="continuous">
    <origin
      xyz="0.14 0 0.0537"
      rpy="0 0 0.13433" />
    <parent
      link="left_leg2" />
    <child
      link="left_wheel" />
    <axis
      xyz="0 0 -1" />
  </joint>
  <link
    name="left_leg3">
    <inertial>
      <origin
        xyz="0.072113 0.016825 -0.008"
        rpy="0 0 0" />
      <mass
        value="0.071103" />
      <inertia
        ixx="1.6657E-05"
        ixy="-5.5246E-06"
        ixz="3.9598E-14"
        iyy="0.00017966"
        iyz="-6.5493E-15"
        izz="0.00019328" />
    </inertial>
    <visual>
      <origin
        xyz="0 0 0"
        rpy="0 0 0" />
      <geometry>
        <mesh
          filename="../meshes/left_leg3.STL" />
      </geometry>
      <material
        name="">
        <color
          rgba="0.62745 0.62745 0.62745 1" />
      </material>
    </visual>
    <collision>
      <origin
        xyz="0 0 0"
        rpy="0 0 0" />
      <geometry>
        <mesh
          filename="../meshes/left_leg3.STL" />
      </geometry>
    </collision>
  </link>
  <joint
    name="left_j5"
    type="continuous">
    <origin
      xyz="0.09 0 0"
      rpy="0 0 -2.8729" />
    <parent
      link="left_motor" />
    <child
      link="left_leg3" />
    <axis
      xyz="0 0 1" />
  </joint>
  <link
    name="right_motor">
    <inertial>
      <origin
        xyz="0.0012044 1.8203E-07 0.066749"
        rpy="0 0 0" />
      <mass
        value="1.3838" />
      <inertia
        ixx="0.003352"
        ixy="-2.6527E-09"
        ixz="6.5914E-05"
        iyy="0.0034908"
        iyz="-7.2968E-10"
        izz="0.0034856" />
    </inertial>
    <visual>
      <origin
        xyz="0 0 0"
        rpy="0 0 0" />
      <geometry>
        <mesh
          filename="../meshes/right_motor.STL" />
      </geometry>
      <material
        name="">
        <color
          rgba="0.62745 0.62745 0.62745 1" />
      </material>
    </visual>
    <collision>
      <origin
        xyz="0 0 0"
        rpy="0 0 0" />
      <geometry>
        <mesh
          filename="../meshes/right_motor.STL" />
      </geometry>
    </collision>
  </link>
  <joint
    name="right_j4"
    type="continuous">
    <origin
      xyz="0 -0.18755 0"
      rpy="1.5708 0.13433 3.1416" />
    <parent
      link="base_link" />
    <child
      link="right_motor" />
    <axis
      xyz="0 0 -1" />
  </joint>
  <link
    name="right_leg1">
    <inertial>
      <origin
        xyz="0.056675 -0.014633 0.0079998"
        rpy="0 0 0" />
      <mass
        value="0.10382" />
      <inertia
        ixx="3.6972E-05"
        ixy="2.4106E-05"
        ixz="-4.3686E-10"
        iyy="0.00029278"
        iyz="4.1459E-11"
        izz="0.00032532" />
    </inertial>
    <visual>
      <origin
        xyz="0 0 0"
        rpy="0 0 0" />
      <geometry>
        <mesh
          filename="../meshes/right_leg1.STL" />
      </geometry>
      <material
        name="">
        <color
          rgba="0.62745 0.62745 0.62745 1" />
      </material>
    </visual>
    <collision>
      <origin
        xyz="0 0 0"
        rpy="0 0 0" />
      <geometry>
        <mesh
          filename="../meshes/right_leg1.STL" />
      </geometry>
    </collision>
  </link>
  <joint
    name="right_j1"
    type="continuous">
    <origin
      xyz="0 0 0"
      rpy="0 0 -2.8729" />
    <parent
      link="right_motor" />
    <child
      link="right_leg1" />
    <axis
      xyz="0 0 -1" />
  </joint>
  <link
    name="right_leg2">
    <inertial>
      <origin
        xyz="0.092381 7.2069E-07 -0.012349"
        rpy="0 0 0" />
      <mass
        value="0.18218" />
      <inertia
        ixx="4.1372E-05"
        ixy="5.1777E-09"
        ixz="7.3659E-06"
        iyy="0.00048219"
        iyz="4.5225E-11"
        izz="0.00050441" />
    </inertial>
    <visual>
      <origin
        xyz="0 0 0"
        rpy="0 0 0" />
      <geometry>
        <mesh
          filename="../meshes/right_leg2.STL" />
      </geometry>
      <material
        name="">
        <color
          rgba="0.62745 0.62745 0.62745 1" />
      </material>
    </visual>
    <collision>
      <origin
        xyz="0 0 0"
        rpy="0 0 0" />
      <geometry>
        <mesh
          filename="../meshes/right_leg2.STL" />
      </geometry>
    </collision>
  </link>
  <joint
    name="right_j2"
    type="continuous">
    <origin
      xyz="0.14 0 0"
      rpy="0 0 2.8729" />
    <parent
      link="right_leg1" />
    <child
      link="right_leg2" />
    <axis
      xyz="0 0 1" />
  </joint>
  <link
    name="right_wheel">
    <inertial>
      <origin
        xyz="-1.1211E-08 -1.346E-08 5.0793E-09"
        rpy="0 0 0" />
      <mass
        value="2.9494" />
      <inertia
        ixx="0.0069339"
        ixy="-1.3146E-07"
        ixz="-3.0392E-09"
        iyy="0.0069339"
        iyz="-3.5756E-09"
        izz="0.012567" />
    </inertial>
    <visual>
      <origin
        xyz="0 0 0"
        rpy="0 0 0" />
      <geometry>
        <mesh
          filename="../meshes/right_wheel.STL" />
      </geometry>
      <material
        name="">
        <color
          rgba="0.69804 0.69804 0.69804 1" />
        <texture
          filename="../textures/0a6c950e073a74d2e5cfa0c785a44257.jpg" />
      </material>
    </visual>
    <collision>
      <origin
        xyz="0 0 0"
        rpy="0 0 0" />
      <geometry>
        <mesh
          filename="../meshes/right_wheel.STL" />
      </geometry>
    </collision>
  </link>
  <joint
    name="right_j3"
    type="continuous">
    <origin
      xyz="0.14 0 -0.0537"
      rpy="0 0 -3.0073" />
    <parent
      link="right_leg2" />
    <child
      link="right_wheel" />
    <axis
      xyz="0 0 -1" />
  </joint>
  <link
    name="right_leg3">
    <inertial>
      <origin
        xyz="0.072113 0.016825 0.008"
        rpy="0 0 0" />
      <mass
        value="0.071103" />
      <inertia
        ixx="1.6657E-05"
        ixy="-5.5246E-06"
        ixz="1.4852E-14"
        iyy="0.00017966"
        iyz="-6.5194E-14"
        izz="0.00019328" />
    </inertial>
    <visual>
      <origin
        xyz="0 0 0"
        rpy="0 0 0" />
      <geometry>
        <mesh
          filename="../meshes/right_leg3.STL" />
      </geometry>
      <material
        name="">
        <color
          rgba="0.62745 0.62745 0.62745 1" />
      </material>
    </visual>
    <collision>
      <origin
        xyz="0 0 0"
        rpy="0 0 0" />
      <geometry>
        <mesh
          filename="../meshes/right_leg3.STL" />
      </geometry>
    </collision>
  </link>
  <joint
    name="right_j5"
    type="continuous">
    <origin
      xyz="0.09 0 0"
      rpy="0 0 -2.8729" />
    <parent
      link="right_motor" />
    <child
      link="right_leg3" />
    <axis
      xyz="0 0 1" />
  </joint>
  <link
    name="little_wheel_left1">
    <inertial>
      <origin
        xyz="6.2073E-13 0.012 -8.4308E-16"
        rpy="0 0 0" />
      <mass
        value="0.065911" />
      <inertia
        ixx="1.7479E-05"
        ixy="5.9069E-16"
        ixz="1.6511E-28"
        iyy="2.8907E-05"
        iyz="3.1935E-18"
        izz="1.7479E-05" />
    </inertial>
    <visual>
      <origin
        xyz="0 0 0"
        rpy="0 0 0" />
      <geometry>
        <mesh
          filename="../meshes/little_wheel_left1.STL" />
      </geometry>
      <material
        name="">
        <color
          rgba="1 1 1 1" />
      </material>
    </visual>
    <collision>
      <origin
        xyz="0 0 0"
        rpy="0 0 0" />
      <geometry>
        <mesh
          filename="../meshes/little_wheel_left1.STL" />
      </geometry>
    </collision>
  </link>
  <joint
    name="little_wheel_left_j1"
    type="continuous">
    <origin
      xyz="0.1562 0.08775 -0.101"
      rpy="0 0 0" />
    <parent
      link="base_link" />
    <child
      link="little_wheel_left1" />
    <axis
      xyz="0 1 0" />
  </joint>
  <link
    name="little_wheel_left2">
    <inertial>
      <origin
        xyz="5.63681046283904E-13 0.0120000000041354 2.68465805142171E-13"
        rpy="0 0 0" />
      <mass
        value="0.0659111230464467" />
      <inertia
        ixx="1.74789440963693E-05"
        ixy="5.34764281964642E-16"
        ixz="-4.2351647362715E-22"
        iyy="2.89067108351503E-05"
        iyz="2.53441128574976E-16"
        izz="1.74789440963693E-05" />
    </inertial>
    <visual>
      <origin
        xyz="0 0 0"
        rpy="0 0 0" />
      <geometry>
        <mesh
          filename="../meshes/little_wheel_left2.STL" />
      </geometry>
      <material
        name="">
        <color
          rgba="1 1 1 1" />
      </material>
    </visual>
    <collision>
      <origin
        xyz="0 0 0"
        rpy="0 0 0" />
      <geometry>
        <mesh
          filename="../meshes/little_wheel_left2.STL" />
      </geometry>
    </collision>
  </link>
  <joint
    name="little_wheel_left_j2"
    type="continuous">
    <origin
      xyz="-0.1135 0.08775 -0.101"
      rpy="0 0.4448 0" />
    <parent
      link="base_link" />
    <child
      link="little_wheel_left2" />
    <axis
      xyz="0 1 0" />
  </joint>
  <link
    name="little_wheel_right1">
    <inertial>
      <origin
        xyz="-6.784E-13 -0.012 -3.9468E-14"
        rpy="0 0 0" />
      <mass
        value="0.065911" />
      <inertia
        ixx="1.7479E-05"
        ixy="5.931E-16"
        ixz="6.6414E-32"
        iyy="2.8907E-05"
        iyz="1.4721E-21"
        izz="1.7479E-05" />
    </inertial>
    <visual>
      <origin
        xyz="0 0 0"
        rpy="0 0 0" />
      <geometry>
        <mesh
          filename="../meshes/little_wheel_right1.STL" />
      </geometry>
      <material
        name="">
        <color
          rgba="1 1 1 1" />
      </material>
    </visual>
    <collision>
      <origin
        xyz="0 0 0"
        rpy="0 0 0" />
      <geometry>
        <mesh
          filename="../meshes/little_wheel_right1.STL" />
      </geometry>
    </collision>
  </link>
  <joint
    name="little_wheel_right_j1"
    type="continuous">
    <origin
      xyz="0.1562 -0.08775 -0.101"
      rpy="0 0 0" />
    <parent
      link="base_link" />
    <child
      link="little_wheel_right1" />
    <axis
      xyz="0 1 0" />
  </joint>
  <link
    name="little_wheel_right2">
    <inertial>
      <origin
        xyz="-6.2098E-13 -0.012 9.2634E-16"
        rpy="0 0 0" />
      <mass
        value="0.065911" />
      <inertia
        ixx="1.7479E-05"
        ixy="5.9178E-16"
        ixz="-6.8314E-29"
        iyy="2.8907E-05"
        iyz="-1.3191E-18"
        izz="1.7479E-05" />
    </inertial>
    <visual>
      <origin
        xyz="0 0 0"
        rpy="0 0 0" />
      <geometry>
        <mesh
          filename="../meshes/little_wheel_right2.STL" />
      </geometry>
      <material
        name="">
        <color
          rgba="1 1 1 1" />
      </material>
    </visual>
    <collision>
      <origin
        xyz="0 0 0"
        rpy="0 0 0" />
      <geometry>
        <mesh
          filename="../meshes/little_wheel_right2.STL" />
      </geometry>
    </collision>
  </link>
  <joint
    name="little_wheel_right_j2"
    type="continuous">
    <origin
      xyz="-0.1135 -0.08775 -0.101"
      rpy="0 0 0" />
    <parent
      link="base_link" />
    <child
      link="little_wheel_right2" />
    <axis
      xyz="0 1 0" />
  </joint>

</robot>